IndexError in line 216 of /home/PERSONALE/eugenio.fonzi2/WESPipeline/snakefile_03.py:
index 0 is out of bounds for axis 0 with size 0
  File "/home/PERSONALE/eugenio.fonzi2/WESPipeline/snakefile_03.py", line 216, in <module>
  File "/home/PERSONALE/eugenio.fonzi2/miniconda3/lib/python3.6/site-packages/pandas/core/indexes/base.py", line 1743, in __getitem__
